/*


疑问： 下面的信息是通过printStackTrace方法打印出来，那么异常对象从何而来呢？ 
	Exception in thread "main" java.lang.ArithmeticException: / by zero
        at Demo10.div(Demo10.java:10)
        at Demo10.main(Demo10.java:5)
	
jvm运行到a/b这个语句的时候，发现b为0，除数为0在我们现实生活中是属于
不正常的情况，jvm一旦发现了这种不正常的情况时候，那么jvm就会马上创建
一个对应的异常对象，并且会调用这个异常对象 的printStackTrace的方法来处理。


异常的处理：

	 方式一：捕获处理

	  捕获处理的格式：  try-catch块外面的代码可以正常执行
			
			try{
				可能发生异常的代码；

			}catch(捕获的异常类型 变量名){
				处理异常的代码....
			}
	
		
		捕获处理要注意的细节：
			1. 如果try块中代码出了异常经过了处理之后，那么try-catch块外面的代码可以正常执行。
			2. 如果try块中出了异常的代码，那么在try块中出现异常代码后面的代码是不会执行了。
			3. 一个try块后面是可以跟有多个catch块的，也就是一个try块可以捕获多种异常的类型。
			4. 一个try块可以捕获多种异常的类型,但是捕获的异常类型必须从小到大进行捕获，否则编译报错。


疑问一 : 异常的处理感觉没有多大作用，因为都是输出一个话而已?
		异常处理非常有用，只不过是由于我们目前所接触的知识点太过于局限而已。

很重要
疑问二： 以后捕获处理 的时候是否就是捕获Exception即可？
	错的，因为我们在现实开发中遇到不同的异常类型的时候，我往往会有不同 的处理方式。
	所以要分开不同的异常类型处理。*******************************************************
*/


class Demo7 
{
	public static void main(String[] args) 
	{
		//System.out.println("Hello World!");
        
        int arr[]=null;
       // SumData(10,0,arr[]);   //除数为0 报异常
       SumData(10,0,arr);
	}


	public static  void SumData(int a, int b, int  arr[]){
	 int c=0;
	  /*
	  c=a/b;
	  System.out.println(c);
      */
    
	  try
	  {
		  c=a/b;
	      System.out.println(c+"______");       //这一句不会执行 因为上一句已经异常了 
		  System.out.println(arr.length);
	  }  //捕获异常类型 都可以是 Exception  类型来进行接收
	  catch (ArithmeticException e)   //异常类型 ArithmeticException    如果try块中代码出了异常经过了处理之后，那么try-catch块外面的代码可以正常执行。
	  { 
		  System.out.println(e.toString());
		  System.out.println("________________________________________");

		  e.printStackTrace();
	  }
	  /*
	  catch(NullPointerException e){  //空指针异常
	   System.out.println(e.toString());  
	  }*/
	  catch(Exception e){          //  一个try块可以捕获多种异常的类型,但是捕获的异常类型必须从小到大进行捕获，否则编译报错。
	  System.out.println("我是父类异常"); 
	  }
	  c=3;                           //try-catch块外面的代码可以正常执行。
	  System.out.println(c);
	  System.out.println("我可以继续执行~~~");
	}
}
